<sdf version='1.7'>
  <world name='default'>
    <light name='sun' type='directional'>
      <cast_shadows>1</cast_shadows>
      <pose>0 0 10 0 -0 0</pose>
      <diffuse>0.8 0.8 0.8 1</diffuse>
      <specular>0.2 0.2 0.2 1</specular>
      <attenuation>
        <range>1000</range>
        <constant>0.9</constant>
        <linear>0.01</linear>
        <quadratic>0.001</quadratic>
      </attenuation>
      <direction>-0.5 0.1 -0.9</direction>
      <spot>
        <inner_angle>0</inner_angle>
        <outer_angle>0</outer_angle>
        <falloff>0</falloff>
      </spot>
    </light>
    <model name='ground_plane'>
      <static>1</static>
      <link name='link'>
        <collision name='collision'>
          <geometry>
            <plane>
              <normal>0 0 1</normal>
              <size>100 100</size>
            </plane>
          </geometry>
          <surface>
            <contact>
              <collide_bitmask>65535</collide_bitmask>
              <ode/>
            </contact>
            <friction>
              <ode>
                <mu>100</mu>
                <mu2>50</mu2>
              </ode>
              <torsional>
                <ode/>
              </torsional>
            </friction>
            <bounce/>
          </surface>
          <max_contacts>10</max_contacts>
        </collision>
        <visual name='visual'>
          <cast_shadows>0</cast_shadows>
          <geometry>
            <plane>
              <normal>0 0 1</normal>
              <size>100 100</size>
            </plane>
          </geometry>
          <material>
            <script>
              <uri>file://media/materials/scripts/gazebo.material</uri>
              <name>Gazebo/Grey</name>
            </script>
          </material>
        </visual>
        <self_collide>0</self_collide>
        <enable_wind>0</enable_wind>
        <kinematic>0</kinematic>
      </link>
    </model>
    <gravity>0 0 -9.8</gravity>
    <magnetic_field>6e-06 2.3e-05 -4.2e-05</magnetic_field>
    <atmosphere type='adiabatic'/>
    <physics type='ode'>
      <max_step_size>0.001</max_step_size>
      <real_time_factor>1</real_time_factor>
      <real_time_update_rate>1000</real_time_update_rate>
    </physics>
    <scene>
      <ambient>0.4 0.4 0.4 1</ambient>
      <background>0.7 0.7 0.7 1</background>
      <shadows>1</shadows>
    </scene>
    <wind/>
    <spherical_coordinates>
      <surface_model>EARTH_WGS84</surface_model>
      <latitude_deg>0</latitude_deg>
      <longitude_deg>0</longitude_deg>
      <elevation>0</elevation>
      <heading_deg>0</heading_deg>
    </spherical_coordinates>
    <model name='open_base'>
      <link name='origin_link'>
        <inertial>
          <pose>0 0 0.021177 0 -0 0</pose>
          <mass>0.0846294</mass>
          <inertia>
            <ixx>3.0279e-05</ixx>
            <ixy>0</ixy>
            <ixz>0</ixz>
            <iyy>3.0279e-05</iyy>
            <iyz>0</iyz>
            <izz>4.91616e-05</izz>
          </inertia>
        </inertial>
        <collision name='origin_link_fixed_joint_lump__base_link_collision'>
          <pose>0 0 0.01905 0 -0 0</pose>
          <geometry>
            <mesh>
              <scale>1 1 1</scale>
              <uri>/home/nikita/omni_ws/src/open_base/mesh/base.stl</uri>
            </mesh>
          </geometry>
          <max_contacts>10</max_contacts>
          <surface>
            <contact>
              <ode/>
            </contact>
            <bounce/>
            <friction>
              <torsional>
                <ode/>
              </torsional>
              <ode/>
            </friction>
          </surface>
        </collision>
        <collision name='origin_link_fixed_joint_lump__five_sonar_link_collision_1'>
          <pose>0 0.04 0.04905 0 -0 1.5708</pose>
          <geometry>
            <box>
              <size>0.01 0.01 0.01</size>
            </box>
          </geometry>
          <surface>
            <contact>
              <ode/>
            </contact>
            <friction>
              <ode/>
              <torsional>
                <ode/>
              </torsional>
            </friction>
            <bounce/>
          </surface>
          <max_contacts>10</max_contacts>
        </collision>
        <collision name='origin_link_fixed_joint_lump__for_sonar_link_collision_2'>
          <pose>-0.034641 -0.02 0.04905 0 0 -2.61799</pose>
          <geometry>
            <box>
              <size>0.01 0.01 0.01</size>
            </box>
          </geometry>
          <surface>
            <contact>
              <ode/>
            </contact>
            <friction>
              <ode/>
              <torsional>
                <ode/>
              </torsional>
            </friction>
            <bounce/>
          </surface>
          <max_contacts>10</max_contacts>
        </collision>
        <collision name='origin_link_fixed_joint_lump__one_sonar_link_collision_3'>
          <pose>0 -0.04 0.04905 0 0 -1.5708</pose>
          <geometry>
            <box>
              <size>0.01 0.01 0.01</size>
            </box>
          </geometry>
          <surface>
            <contact>
              <ode/>
            </contact>
            <friction>
              <ode/>
              <torsional>
                <ode/>
              </torsional>
            </friction>
            <bounce/>
          </surface>
          <max_contacts>10</max_contacts>
        </collision>
        <collision name='origin_link_fixed_joint_lump__six_sonar_link_collision_4'>
          <pose>0.034641 -0.02 0.04905 0 0 -0.523599</pose>
          <geometry>
            <box>
              <size>0.01 0.01 0.01</size>
            </box>
          </geometry>
          <surface>
            <contact>
              <ode/>
            </contact>
            <friction>
              <ode/>
              <torsional>
                <ode/>
              </torsional>
            </friction>
            <bounce/>
          </surface>
          <max_contacts>10</max_contacts>
        </collision>
        <collision name='origin_link_fixed_joint_lump__three_sonar_link_collision_5'>
          <pose>0.034641 0.02 0.04905 0 -0 0.523599</pose>
          <geometry>
            <box>
              <size>0.01 0.01 0.01</size>
            </box>
          </geometry>
          <surface>
            <contact>
              <ode/>
            </contact>
            <friction>
              <ode/>
              <torsional>
                <ode/>
              </torsional>
            </friction>
            <bounce/>
          </surface>
          <max_contacts>10</max_contacts>
        </collision>
        <collision name='origin_link_fixed_joint_lump__two_sonar_link_collision_6'>
          <pose>-0.034641 0.02 0.04905 0 -0 2.61799</pose>
          <geometry>
            <box>
              <size>0.01 0.01 0.01</size>
            </box>
          </geometry>
          <surface>
            <contact>
              <ode/>
            </contact>
            <friction>
              <ode/>
              <torsional>
                <ode/>
              </torsional>
            </friction>
            <bounce/>
          </surface>
          <max_contacts>10</max_contacts>
        </collision>
        <visual name='origin_link_fixed_joint_lump__base_link_visual'>
          <pose>0 0 0.01905 0 -0 0</pose>
          <geometry>
            <mesh>
              <scale>1 1 1</scale>
              <uri>/home/nikita/omni_ws/src/open_base/mesh/base.stl</uri>
            </mesh>
          </geometry>
        </visual>
        <visual name='origin_link_fixed_joint_lump__five_sonar_link_visual_1'>
          <pose>0 0.04 0.04905 0 -0 1.5708</pose>
          <geometry>
            <mesh>
              <scale>1 1 1</scale>
              <uri>/opt/ros/noetic/share/hector_sensors_description/meshes/sonar_sensor/max_sonar_ez4.dae</uri>
            </mesh>
          </geometry>
        </visual>
        <visual name='origin_link_fixed_joint_lump__for_sonar_link_visual_2'>
          <pose>-0.034641 -0.02 0.04905 0 0 -2.61799</pose>
          <geometry>
            <mesh>
              <scale>1 1 1</scale>
              <uri>/opt/ros/noetic/share/hector_sensors_description/meshes/sonar_sensor/max_sonar_ez4.dae</uri>
            </mesh>
          </geometry>
        </visual>
        <visual name='origin_link_fixed_joint_lump__one_sonar_link_visual_3'>
          <pose>0 -0.04 0.04905 0 0 -1.5708</pose>
          <geometry>
            <mesh>
              <scale>1 1 1</scale>
              <uri>/opt/ros/noetic/share/hector_sensors_description/meshes/sonar_sensor/max_sonar_ez4.dae</uri>
            </mesh>
          </geometry>
        </visual>
        <visual name='origin_link_fixed_joint_lump__six_sonar_link_visual_4'>
          <pose>0.034641 -0.02 0.04905 0 0 -0.523599</pose>
          <geometry>
            <mesh>
              <scale>1 1 1</scale>
              <uri>/opt/ros/noetic/share/hector_sensors_description/meshes/sonar_sensor/max_sonar_ez4.dae</uri>
            </mesh>
          </geometry>
        </visual>
        <visual name='origin_link_fixed_joint_lump__three_sonar_link_visual_5'>
          <pose>0.034641 0.02 0.04905 0 -0 0.523599</pose>
          <geometry>
            <mesh>
              <scale>1 1 1</scale>
              <uri>/opt/ros/noetic/share/hector_sensors_description/meshes/sonar_sensor/max_sonar_ez4.dae</uri>
            </mesh>
          </geometry>
        </visual>
        <visual name='origin_link_fixed_joint_lump__two_sonar_link_visual_6'>
          <pose>-0.034641 0.02 0.04905 0 -0 2.61799</pose>
          <geometry>
            <mesh>
              <scale>1 1 1</scale>
              <uri>/opt/ros/noetic/share/hector_sensors_description/meshes/sonar_sensor/max_sonar_ez4.dae</uri>
            </mesh>
          </geometry>
        </visual>
        <sensor name='five_sonar' type='ray'>
          <always_on>1</always_on>
          <update_rate>5</update_rate>
          <visualize>0</visualize>
          <ray>
            <scan>
              <horizontal>
                <samples>1</samples>
                <resolution>1</resolution>
                <min_angle>-0.05</min_angle>
                <max_angle>0.05</max_angle>
              </horizontal>
              <vertical>
                <samples>1</samples>
                <resolution>1</resolution>
                <min_angle>-0.05</min_angle>
                <max_angle>0.05</max_angle>
              </vertical>
            </scan>
            <range>
              <min>0.1</min>
              <max>0.8</max>
              <resolution>0.01</resolution>
            </range>
          </ray>
          <plugin name='gazebo_ros_five_sonar_controller' filename='libhector_gazebo_ros_sonar.so'>
            <gaussianNoise>0.005</gaussianNoise>
            <topicName>five_sonar</topicName>
            <frameId>five_sonar_link</frameId>
            <robotNamespace>/open_base/</robotNamespace>
          </plugin>
          <pose>0 0.04 0.04905 0 -0 1.5708</pose>
        </sensor>
        <sensor name='for_sonar' type='ray'>
          <always_on>1</always_on>
          <update_rate>5</update_rate>
          <visualize>0</visualize>
          <ray>
            <scan>
              <horizontal>
                <samples>1</samples>
                <resolution>1</resolution>
                <min_angle>-0.05</min_angle>
                <max_angle>0.05</max_angle>
              </horizontal>
              <vertical>
                <samples>1</samples>
                <resolution>1</resolution>
                <min_angle>-0.05</min_angle>
                <max_angle>0.05</max_angle>
              </vertical>
            </scan>
            <range>
              <min>0.1</min>
              <max>0.8</max>
              <resolution>0.01</resolution>
            </range>
          </ray>
          <plugin name='gazebo_ros_for_sonar_controller' filename='libhector_gazebo_ros_sonar.so'>
            <gaussianNoise>0.005</gaussianNoise>
            <topicName>for_sonar</topicName>
            <frameId>for_sonar_link</frameId>
            <robotNamespace>/open_base/</robotNamespace>
          </plugin>
          <pose>-0.034641 -0.02 0.04905 0 -0 -2.61799</pose>
        </sensor>
        <sensor name='one_sonar' type='ray'>
          <always_on>1</always_on>
          <update_rate>5</update_rate>
          <visualize>0</visualize>
          <ray>
            <scan>
              <horizontal>
                <samples>1</samples>
                <resolution>1</resolution>
                <min_angle>-0.05</min_angle>
                <max_angle>0.05</max_angle>
              </horizontal>
              <vertical>
                <samples>1</samples>
                <resolution>1</resolution>
                <min_angle>-0.05</min_angle>
                <max_angle>0.05</max_angle>
              </vertical>
            </scan>
            <range>
              <min>0.1</min>
              <max>0.8</max>
              <resolution>0.01</resolution>
            </range>
          </ray>
          <plugin name='gazebo_ros_one_sonar_controller' filename='libhector_gazebo_ros_sonar.so'>
            <gaussianNoise>0.005</gaussianNoise>
            <topicName>one_sonar</topicName>
            <frameId>one_sonar_link</frameId>
            <robotNamespace>/open_base/</robotNamespace>
          </plugin>
          <pose>0 -0.04 0.04905 0 -0 -1.5708</pose>
        </sensor>
        <sensor name='six_sonar' type='ray'>
          <always_on>1</always_on>
          <update_rate>5</update_rate>
          <visualize>0</visualize>
          <ray>
            <scan>
              <horizontal>
                <samples>1</samples>
                <resolution>1</resolution>
                <min_angle>-0.05</min_angle>
                <max_angle>0.05</max_angle>
              </horizontal>
              <vertical>
                <samples>1</samples>
                <resolution>1</resolution>
                <min_angle>-0.05</min_angle>
                <max_angle>0.05</max_angle>
              </vertical>
            </scan>
            <range>
              <min>0.1</min>
              <max>0.8</max>
              <resolution>0.01</resolution>
            </range>
          </ray>
          <plugin name='gazebo_ros_six_sonar_controller' filename='libhector_gazebo_ros_sonar.so'>
            <gaussianNoise>0.005</gaussianNoise>
            <topicName>six_sonar</topicName>
            <frameId>six_sonar_link</frameId>
            <robotNamespace>/open_base/</robotNamespace>
          </plugin>
          <pose>0.034641 -0.02 0.04905 0 -0 -0.523599</pose>
        </sensor>
        <sensor name='three_sonar' type='ray'>
          <always_on>1</always_on>
          <update_rate>5</update_rate>
          <visualize>0</visualize>
          <ray>
            <scan>
              <horizontal>
                <samples>1</samples>
                <resolution>1</resolution>
                <min_angle>-0.05</min_angle>
                <max_angle>0.05</max_angle>
              </horizontal>
              <vertical>
                <samples>1</samples>
                <resolution>1</resolution>
                <min_angle>-0.05</min_angle>
                <max_angle>0.05</max_angle>
              </vertical>
            </scan>
            <range>
              <min>0.1</min>
              <max>0.8</max>
              <resolution>0.01</resolution>
            </range>
          </ray>
          <plugin name='gazebo_ros_three_sonar_controller' filename='libhector_gazebo_ros_sonar.so'>
            <gaussianNoise>0.005</gaussianNoise>
            <topicName>three_sonar</topicName>
            <frameId>three_sonar_link</frameId>
            <robotNamespace>/open_base/</robotNamespace>
          </plugin>
          <pose>0.034641 0.02 0.04905 0 -0 0.523599</pose>
        </sensor>
        <sensor name='two_sonar' type='ray'>
          <always_on>1</always_on>
          <update_rate>5</update_rate>
          <visualize>0</visualize>
          <ray>
            <scan>
              <horizontal>
                <samples>1</samples>
                <resolution>1</resolution>
                <min_angle>-0.05</min_angle>
                <max_angle>0.05</max_angle>
              </horizontal>
              <vertical>
                <samples>1</samples>
                <resolution>1</resolution>
                <min_angle>-0.05</min_angle>
                <max_angle>0.05</max_angle>
              </vertical>
            </scan>
            <range>
              <min>0.1</min>
              <max>0.8</max>
              <resolution>0.01</resolution>
            </range>
          </ray>
          <plugin name='gazebo_ros_two_sonar_controller' filename='libhector_gazebo_ros_sonar.so'>
            <gaussianNoise>0.005</gaussianNoise>
            <topicName>two_sonar</topicName>
            <frameId>two_sonar_link</frameId>
            <robotNamespace>/open_base/</robotNamespace>
          </plugin>
          <pose>-0.034641 0.02 0.04905 0 -0 2.61799</pose>
        </sensor>
        <self_collide>0</self_collide>
        <enable_wind>0</enable_wind>
        <kinematic>0</kinematic>
      </link>
      <joint name='rim_back_joint' type='revolute'>
        <pose relative_to='origin_link'>0 -0.04 0.01905 1.5708 -0 3.14159</pose>
        <parent>origin_link</parent>
        <child>rim_back_link</child>
        <axis>
          <xyz>0 0 1</xyz>
          <limit>
            <lower>-1e+16</lower>
            <upper>1e+16</upper>
          </limit>
          <dynamics>
            <spring_reference>0</spring_reference>
            <spring_stiffness>0</spring_stiffness>
          </dynamics>
        </axis>
      </joint>
      <link name='rim_back_link'>
        <pose relative_to='rim_back_joint'>0 0 0 0 -0 0</pose>
        <inertial>
          <pose>0 0 -0.000343 0 -0 0</pose>
          <mass>0.00835758</mass>
          <inertia>
            <ixx>6.63684e-07</ixx>
            <ixy>0</ixy>
            <ixz>0</ixz>
            <iyy>6.63684e-07</iyy>
            <iyz>0</iyz>
            <izz>9.40333e-07</izz>
          </inertia>
        </inertial>
        <collision name='rim_back_link_collision'>
          <pose>0 0 0 0 -0 0</pose>
          <geometry>
            <mesh>
              <scale>1 1 1</scale>
              <uri>/home/nikita/omni_ws/src/open_base/mesh/rim.stl</uri>
            </mesh>
          </geometry>
          <max_contacts>10</max_contacts>
          <surface>
            <contact>
              <ode/>
            </contact>
            <bounce/>
            <friction>
              <torsional>
                <ode/>
              </torsional>
              <ode/>
            </friction>
          </surface>
        </collision>
        <visual name='rim_back_link_visual'>
          <pose>0 0 0 0 -0 0</pose>
          <geometry>
            <mesh>
              <scale>1 1 1</scale>
              <uri>/home/nikita/omni_ws/src/open_base/mesh/rim.stl</uri>
            </mesh>
          </geometry>
        </visual>
        <self_collide>0</self_collide>
        <enable_wind>0</enable_wind>
        <kinematic>0</kinematic>
      </link>
      <joint name='roller_e_rim_back_joint' type='revolute'>
        <pose relative_to='rim_back_link'>0.01355 0 0.0055 -1.5708 0 0</pose>
        <parent>rim_back_link</parent>
        <child>roller_e_rim_back_link</child>
        <axis>
          <xyz>0 0 1</xyz>
          <limit>
            <lower>-1e+16</lower>
            <upper>1e+16</upper>
          </limit>
          <dynamics>
            <spring_reference>0</spring_reference>
            <spring_stiffness>0</spring_stiffness>
          </dynamics>
        </axis>
      </joint>
      <link name='roller_e_rim_back_link'>
        <pose relative_to='roller_e_rim_back_joint'>0 0 0 0 -0 0</pose>
        <inertial>
          <pose>0 0 0 0 -0 0</pose>
          <mass>0.00113845</mass>
          <inertia>
            <ixx>2.53776e-08</ixx>
            <ixy>0</ixy>
            <ixz>0</ixz>
            <iyy>2.53776e-08</iyy>
            <iyz>0</iyz>
            <izz>1.47666e-08</izz>
          </inertia>
        </inertial>
        <collision name='roller_e_rim_back_link_collision'>
          <pose>0 0 0 0 -0 0</pose>
          <geometry>
            <mesh>
              <scale>1 1 1</scale>
              <uri>/home/nikita/omni_ws/src/open_base/mesh/roller.stl</uri>
            </mesh>
          </geometry>
          <max_contacts>10</max_contacts>
          <surface>
            <contact>
              <ode/>
            </contact>
            <bounce/>
            <friction>
              <torsional>
                <ode/>
              </torsional>
              <ode/>
            </friction>
          </surface>
        </collision>
        <visual name='roller_e_rim_back_link_visual'>
          <pose>0 0 0 0 -0 0</pose>
          <geometry>
            <mesh>
              <scale>1 1 1</scale>
              <uri>/home/nikita/omni_ws/src/open_base/mesh/roller.stl</uri>
            </mesh>
          </geometry>
        </visual>
        <self_collide>0</self_collide>
        <enable_wind>0</enable_wind>
        <kinematic>0</kinematic>
      </link>
      <joint name='roller_n_rim_back_joint' type='revolute'>
        <pose relative_to='rim_back_link'>0 0.01355 0.0055 -1.5708 0 1.5708</pose>
        <parent>rim_back_link</parent>
        <child>roller_n_rim_back_link</child>
        <axis>
          <xyz>0 0 1</xyz>
          <limit>
            <lower>-1e+16</lower>
            <upper>1e+16</upper>
          </limit>
          <dynamics>
            <spring_reference>0</spring_reference>
            <spring_stiffness>0</spring_stiffness>
          </dynamics>
        </axis>
      </joint>
      <link name='roller_n_rim_back_link'>
        <pose relative_to='roller_n_rim_back_joint'>0 0 0 0 -0 0</pose>
        <inertial>
          <pose>0 0 0 0 -0 0</pose>
          <mass>0.00113845</mass>
          <inertia>
            <ixx>2.53776e-08</ixx>
            <ixy>0</ixy>
            <ixz>0</ixz>
            <iyy>2.53776e-08</iyy>
            <iyz>0</iyz>
            <izz>1.47666e-08</izz>
          </inertia>
        </inertial>
        <collision name='roller_n_rim_back_link_collision'>
          <pose>0 0 0 0 -0 0</pose>
          <geometry>
            <mesh>
              <scale>1 1 1</scale>
              <uri>/home/nikita/omni_ws/src/open_base/mesh/roller.stl</uri>
            </mesh>
          </geometry>
          <max_contacts>10</max_contacts>
          <surface>
            <contact>
              <ode/>
            </contact>
            <bounce/>
            <friction>
              <torsional>
                <ode/>
              </torsional>
              <ode/>
            </friction>
          </surface>
        </collision>
        <visual name='roller_n_rim_back_link_visual'>
          <pose>0 0 0 0 -0 0</pose>
          <geometry>
            <mesh>
              <scale>1 1 1</scale>
              <uri>/home/nikita/omni_ws/src/open_base/mesh/roller.stl</uri>
            </mesh>
          </geometry>
        </visual>
        <self_collide>0</self_collide>
        <enable_wind>0</enable_wind>
        <kinematic>0</kinematic>
      </link>
      <joint name='roller_ne_rim_back_joint' type='revolute'>
        <pose relative_to='rim_back_link'>0.009581 0.009581 -0.0055 -1.5708 -0 0.785398</pose>
        <parent>rim_back_link</parent>
        <child>roller_ne_rim_back_link</child>
        <axis>
          <xyz>0 0 1</xyz>
          <limit>
            <lower>-1e+16</lower>
            <upper>1e+16</upper>
          </limit>
          <dynamics>
            <spring_reference>0</spring_reference>
            <spring_stiffness>0</spring_stiffness>
          </dynamics>
        </axis>
      </joint>
      <link name='roller_ne_rim_back_link'>
        <pose relative_to='roller_ne_rim_back_joint'>0 0 0 0 -0 0</pose>
        <inertial>
          <pose>0 0 0 0 -0 0</pose>
          <mass>0.00113845</mass>
          <inertia>
            <ixx>2.53776e-08</ixx>
            <ixy>0</ixy>
            <ixz>0</ixz>
            <iyy>2.53776e-08</iyy>
            <iyz>0</iyz>
            <izz>1.47666e-08</izz>
          </inertia>
        </inertial>
        <collision name='roller_ne_rim_back_link_collision'>
          <pose>0 0 0 0 -0 0</pose>
          <geometry>
            <mesh>
              <scale>1 1 1</scale>
              <uri>/home/nikita/omni_ws/src/open_base/mesh/roller.stl</uri>
            </mesh>
          </geometry>
          <max_contacts>10</max_contacts>
          <surface>
            <contact>
              <ode/>
            </contact>
            <bounce/>
            <friction>
              <torsional>
                <ode/>
              </torsional>
              <ode/>
            </friction>
          </surface>
        </collision>
        <visual name='roller_ne_rim_back_link_visual'>
          <pose>0 0 0 0 -0 0</pose>
          <geometry>
            <mesh>
              <scale>1 1 1</scale>
              <uri>/home/nikita/omni_ws/src/open_base/mesh/roller.stl</uri>
            </mesh>
          </geometry>
        </visual>
        <self_collide>0</self_collide>
        <enable_wind>0</enable_wind>
        <kinematic>0</kinematic>
      </link>
      <joint name='roller_nw_rim_back_joint' type='revolute'>
        <pose relative_to='rim_back_link'>-0.009581 0.009581 -0.0055 -1.5708 -0 2.35619</pose>
        <parent>rim_back_link</parent>
        <child>roller_nw_rim_back_link</child>
        <axis>
          <xyz>0 0 1</xyz>
          <limit>
            <lower>-1e+16</lower>
            <upper>1e+16</upper>
          </limit>
          <dynamics>
            <spring_reference>0</spring_reference>
            <spring_stiffness>0</spring_stiffness>
          </dynamics>
        </axis>
      </joint>
      <link name='roller_nw_rim_back_link'>
        <pose relative_to='roller_nw_rim_back_joint'>0 0 0 0 -0 0</pose>
        <inertial>
          <pose>0 0 0 0 -0 0</pose>
          <mass>0.00113845</mass>
          <inertia>
            <ixx>2.53776e-08</ixx>
            <ixy>0</ixy>
            <ixz>0</ixz>
            <iyy>2.53776e-08</iyy>
            <iyz>0</iyz>
            <izz>1.47666e-08</izz>
          </inertia>
        </inertial>
        <collision name='roller_nw_rim_back_link_collision'>
          <pose>0 0 0 0 -0 0</pose>
          <geometry>
            <mesh>
              <scale>1 1 1</scale>
              <uri>/home/nikita/omni_ws/src/open_base/mesh/roller.stl</uri>
            </mesh>
          </geometry>
          <max_contacts>10</max_contacts>
          <surface>
            <contact>
              <ode/>
            </contact>
            <bounce/>
            <friction>
              <torsional>
                <ode/>
              </torsional>
              <ode/>
            </friction>
          </surface>
        </collision>
        <visual name='roller_nw_rim_back_link_visual'>
          <pose>0 0 0 0 -0 0</pose>
          <geometry>
            <mesh>
              <scale>1 1 1</scale>
              <uri>/home/nikita/omni_ws/src/open_base/mesh/roller.stl</uri>
            </mesh>
          </geometry>
        </visual>
        <self_collide>0</self_collide>
        <enable_wind>0</enable_wind>
        <kinematic>0</kinematic>
      </link>
      <joint name='roller_s_rim_back_joint' type='revolute'>
        <pose relative_to='rim_back_link'>0 -0.01355 0.0055 -1.5708 -0 -1.5708</pose>
        <parent>rim_back_link</parent>
        <child>roller_s_rim_back_link</child>
        <axis>
          <xyz>0 0 1</xyz>
          <limit>
            <lower>-1e+16</lower>
            <upper>1e+16</upper>
          </limit>
          <dynamics>
            <spring_reference>0</spring_reference>
            <spring_stiffness>0</spring_stiffness>
          </dynamics>
        </axis>
      </joint>
      <link name='roller_s_rim_back_link'>
        <pose relative_to='roller_s_rim_back_joint'>0 0 0 0 -0 0</pose>
        <inertial>
          <pose>0 0 0 0 -0 0</pose>
          <mass>0.00113845</mass>
          <inertia>
            <ixx>2.53776e-08</ixx>
            <ixy>0</ixy>
            <ixz>0</ixz>
            <iyy>2.53776e-08</iyy>
            <iyz>0</iyz>
            <izz>1.47666e-08</izz>
          </inertia>
        </inertial>
        <collision name='roller_s_rim_back_link_collision'>
          <pose>0 0 0 0 -0 0</pose>
          <geometry>
            <mesh>
              <scale>1 1 1</scale>
              <uri>/home/nikita/omni_ws/src/open_base/mesh/roller.stl</uri>
            </mesh>
          </geometry>
          <max_contacts>10</max_contacts>
          <surface>
            <contact>
              <ode/>
            </contact>
            <bounce/>
            <friction>
              <torsional>
                <ode/>
              </torsional>
              <ode/>
            </friction>
          </surface>
        </collision>
        <visual name='roller_s_rim_back_link_visual'>
          <pose>0 0 0 0 -0 0</pose>
          <geometry>
            <mesh>
              <scale>1 1 1</scale>
              <uri>/home/nikita/omni_ws/src/open_base/mesh/roller.stl</uri>
            </mesh>
          </geometry>
        </visual>
        <self_collide>0</self_collide>
        <enable_wind>0</enable_wind>
        <kinematic>0</kinematic>
      </link>
      <joint name='roller_se_rim_back_joint' type='revolute'>
        <pose relative_to='rim_back_link'>0.009581 -0.009581 -0.0055 -1.5708 0 -0.785398</pose>
        <parent>rim_back_link</parent>
        <child>roller_se_rim_back_link</child>
        <axis>
          <xyz>0 0 1</xyz>
          <limit>
            <lower>-1e+16</lower>
            <upper>1e+16</upper>
          </limit>
          <dynamics>
            <spring_reference>0</spring_reference>
            <spring_stiffness>0</spring_stiffness>
          </dynamics>
        </axis>
      </joint>
      <link name='roller_se_rim_back_link'>
        <pose relative_to='roller_se_rim_back_joint'>0 0 0 0 -0 0</pose>
        <inertial>
          <pose>0 0 0 0 -0 0</pose>
          <mass>0.00113845</mass>
          <inertia>
            <ixx>2.53776e-08</ixx>
            <ixy>0</ixy>
            <ixz>0</ixz>
            <iyy>2.53776e-08</iyy>
            <iyz>0</iyz>
            <izz>1.47666e-08</izz>
          </inertia>
        </inertial>
        <collision name='roller_se_rim_back_link_collision'>
          <pose>0 0 0 0 -0 0</pose>
          <geometry>
            <mesh>
              <scale>1 1 1</scale>
              <uri>/home/nikita/omni_ws/src/open_base/mesh/roller.stl</uri>
            </mesh>
          </geometry>
          <max_contacts>10</max_contacts>
          <surface>
            <contact>
              <ode/>
            </contact>
            <bounce/>
            <friction>
              <torsional>
                <ode/>
              </torsional>
              <ode/>
            </friction>
          </surface>
        </collision>
        <visual name='roller_se_rim_back_link_visual'>
          <pose>0 0 0 0 -0 0</pose>
          <geometry>
            <mesh>
              <scale>1 1 1</scale>
              <uri>/home/nikita/omni_ws/src/open_base/mesh/roller.stl</uri>
            </mesh>
          </geometry>
        </visual>
        <self_collide>0</self_collide>
        <enable_wind>0</enable_wind>
        <kinematic>0</kinematic>
      </link>
      <joint name='roller_sw_rim_back_joint' type='revolute'>
        <pose relative_to='rim_back_link'>-0.009581 -0.009581 -0.0055 -1.5708 -0 -2.35619</pose>
        <parent>rim_back_link</parent>
        <child>roller_sw_rim_back_link</child>
        <axis>
          <xyz>0 0 1</xyz>
          <limit>
            <lower>-1e+16</lower>
            <upper>1e+16</upper>
          </limit>
          <dynamics>
            <spring_reference>0</spring_reference>
            <spring_stiffness>0</spring_stiffness>
          </dynamics>
        </axis>
      </joint>
      <link name='roller_sw_rim_back_link'>
        <pose relative_to='roller_sw_rim_back_joint'>0 0 0 0 -0 0</pose>
        <inertial>
          <pose>0 0 0 0 -0 0</pose>
          <mass>0.00113845</mass>
          <inertia>
            <ixx>2.53776e-08</ixx>
            <ixy>0</ixy>
            <ixz>0</ixz>
            <iyy>2.53776e-08</iyy>
            <iyz>0</iyz>
            <izz>1.47666e-08</izz>
          </inertia>
        </inertial>
        <collision name='roller_sw_rim_back_link_collision'>
          <pose>0 0 0 0 -0 0</pose>
          <geometry>
            <mesh>
              <scale>1 1 1</scale>
              <uri>/home/nikita/omni_ws/src/open_base/mesh/roller.stl</uri>
            </mesh>
          </geometry>
          <max_contacts>10</max_contacts>
          <surface>
            <contact>
              <ode/>
            </contact>
            <bounce/>
            <friction>
              <torsional>
                <ode/>
              </torsional>
              <ode/>
            </friction>
          </surface>
        </collision>
        <visual name='roller_sw_rim_back_link_visual'>
          <pose>0 0 0 0 -0 0</pose>
          <geometry>
            <mesh>
              <scale>1 1 1</scale>
              <uri>/home/nikita/omni_ws/src/open_base/mesh/roller.stl</uri>
            </mesh>
          </geometry>
        </visual>
        <self_collide>0</self_collide>
        <enable_wind>0</enable_wind>
        <kinematic>0</kinematic>
      </link>
      <joint name='roller_w_rim_back_joint' type='revolute'>
        <pose relative_to='rim_back_link'>-0.01355 0 0.0055 -1.5708 -0 3.14159</pose>
        <parent>rim_back_link</parent>
        <child>roller_w_rim_back_link</child>
        <axis>
          <xyz>0 0 1</xyz>
          <limit>
            <lower>-1e+16</lower>
            <upper>1e+16</upper>
          </limit>
          <dynamics>
            <spring_reference>0</spring_reference>
            <spring_stiffness>0</spring_stiffness>
          </dynamics>
        </axis>
      </joint>
      <link name='roller_w_rim_back_link'>
        <pose relative_to='roller_w_rim_back_joint'>0 0 0 0 -0 0</pose>
        <inertial>
          <pose>0 0 0 0 -0 0</pose>
          <mass>0.00113845</mass>
          <inertia>
            <ixx>2.53776e-08</ixx>
            <ixy>0</ixy>
            <ixz>0</ixz>
            <iyy>2.53776e-08</iyy>
            <iyz>0</iyz>
            <izz>1.47666e-08</izz>
          </inertia>
        </inertial>
        <collision name='roller_w_rim_back_link_collision'>
          <pose>0 0 0 0 -0 0</pose>
          <geometry>
            <mesh>
              <scale>1 1 1</scale>
              <uri>/home/nikita/omni_ws/src/open_base/mesh/roller.stl</uri>
            </mesh>
          </geometry>
          <max_contacts>10</max_contacts>
          <surface>
            <contact>
              <ode/>
            </contact>
            <bounce/>
            <friction>
              <torsional>
                <ode/>
              </torsional>
              <ode/>
            </friction>
          </surface>
        </collision>
        <visual name='roller_w_rim_back_link_visual'>
          <pose>0 0 0 0 -0 0</pose>
          <geometry>
            <mesh>
              <scale>1 1 1</scale>
              <uri>/home/nikita/omni_ws/src/open_base/mesh/roller.stl</uri>
            </mesh>
          </geometry>
        </visual>
        <self_collide>0</self_collide>
        <enable_wind>0</enable_wind>
        <kinematic>0</kinematic>
      </link>
      <joint name='rim_left_joint' type='revolute'>
        <pose relative_to='origin_link'>-0.034641 0.02 0.01905 1.5708 -0 1.0472</pose>
        <parent>origin_link</parent>
        <child>rim_left_link</child>
        <axis>
          <xyz>0 0 1</xyz>
          <limit>
            <lower>-1e+16</lower>
            <upper>1e+16</upper>
          </limit>
          <dynamics>
            <spring_reference>0</spring_reference>
            <spring_stiffness>0</spring_stiffness>
          </dynamics>
        </axis>
      </joint>
      <link name='rim_left_link'>
        <pose relative_to='rim_left_joint'>0 0 0 0 -0 0</pose>
        <inertial>
          <pose>0 0 -0.000343 0 -0 0</pose>
          <mass>0.00835758</mass>
          <inertia>
            <ixx>6.63684e-07</ixx>
            <ixy>0</ixy>
            <ixz>0</ixz>
            <iyy>6.63684e-07</iyy>
            <iyz>0</iyz>
            <izz>9.40333e-07</izz>
          </inertia>
        </inertial>
        <collision name='rim_left_link_collision'>
          <pose>0 0 0 0 -0 0</pose>
          <geometry>
            <mesh>
              <scale>1 1 1</scale>
              <uri>/home/nikita/omni_ws/src/open_base/mesh/rim.stl</uri>
            </mesh>
          </geometry>
          <max_contacts>10</max_contacts>
          <surface>
            <contact>
              <ode/>
            </contact>
            <bounce/>
            <friction>
              <torsional>
                <ode/>
              </torsional>
              <ode/>
            </friction>
          </surface>
        </collision>
        <visual name='rim_left_link_visual'>
          <pose>0 0 0 0 -0 0</pose>
          <geometry>
            <mesh>
              <scale>1 1 1</scale>
              <uri>/home/nikita/omni_ws/src/open_base/mesh/rim.stl</uri>
            </mesh>
          </geometry>
        </visual>
        <self_collide>0</self_collide>
        <enable_wind>0</enable_wind>
        <kinematic>0</kinematic>
      </link>
      <joint name='roller_e_rim_left_joint' type='revolute'>
        <pose relative_to='rim_left_link'>0.01355 0 0.0055 -1.5708 0 0</pose>
        <parent>rim_left_link</parent>
        <child>roller_e_rim_left_link</child>
        <axis>
          <xyz>0 0 1</xyz>
          <limit>
            <lower>-1e+16</lower>
            <upper>1e+16</upper>
          </limit>
          <dynamics>
            <spring_reference>0</spring_reference>
            <spring_stiffness>0</spring_stiffness>
          </dynamics>
        </axis>
      </joint>
      <link name='roller_e_rim_left_link'>
        <pose relative_to='roller_e_rim_left_joint'>0 0 0 0 -0 0</pose>
        <inertial>
          <pose>0 0 0 0 -0 0</pose>
          <mass>0.00113845</mass>
          <inertia>
            <ixx>2.53776e-08</ixx>
            <ixy>0</ixy>
            <ixz>0</ixz>
            <iyy>2.53776e-08</iyy>
            <iyz>0</iyz>
            <izz>1.47666e-08</izz>
          </inertia>
        </inertial>
        <collision name='roller_e_rim_left_link_collision'>
          <pose>0 0 0 0 -0 0</pose>
          <geometry>
            <mesh>
              <scale>1 1 1</scale>
              <uri>/home/nikita/omni_ws/src/open_base/mesh/roller.stl</uri>
            </mesh>
          </geometry>
          <max_contacts>10</max_contacts>
          <surface>
            <contact>
              <ode/>
            </contact>
            <bounce/>
            <friction>
              <torsional>
                <ode/>
              </torsional>
              <ode/>
            </friction>
          </surface>
        </collision>
        <visual name='roller_e_rim_left_link_visual'>
          <pose>0 0 0 0 -0 0</pose>
          <geometry>
            <mesh>
              <scale>1 1 1</scale>
              <uri>/home/nikita/omni_ws/src/open_base/mesh/roller.stl</uri>
            </mesh>
          </geometry>
        </visual>
        <self_collide>0</self_collide>
        <enable_wind>0</enable_wind>
        <kinematic>0</kinematic>
      </link>
      <joint name='roller_n_rim_left_joint' type='revolute'>
        <pose relative_to='rim_left_link'>0 0.01355 0.0055 -1.5708 0 1.5708</pose>
        <parent>rim_left_link</parent>
        <child>roller_n_rim_left_link</child>
        <axis>
          <xyz>0 0 1</xyz>
          <limit>
            <lower>-1e+16</lower>
            <upper>1e+16</upper>
          </limit>
          <dynamics>
            <spring_reference>0</spring_reference>
            <spring_stiffness>0</spring_stiffness>
          </dynamics>
        </axis>
      </joint>
      <link name='roller_n_rim_left_link'>
        <pose relative_to='roller_n_rim_left_joint'>0 0 0 0 -0 0</pose>
        <inertial>
          <pose>0 0 0 0 -0 0</pose>
          <mass>0.00113845</mass>
          <inertia>
            <ixx>2.53776e-08</ixx>
            <ixy>0</ixy>
            <ixz>0</ixz>
            <iyy>2.53776e-08</iyy>
            <iyz>0</iyz>
            <izz>1.47666e-08</izz>
          </inertia>
        </inertial>
        <collision name='roller_n_rim_left_link_collision'>
          <pose>0 0 0 0 -0 0</pose>
          <geometry>
            <mesh>
              <scale>1 1 1</scale>
              <uri>/home/nikita/omni_ws/src/open_base/mesh/roller.stl</uri>
            </mesh>
          </geometry>
          <max_contacts>10</max_contacts>
          <surface>
            <contact>
              <ode/>
            </contact>
            <bounce/>
            <friction>
              <torsional>
                <ode/>
              </torsional>
              <ode/>
            </friction>
          </surface>
        </collision>
        <visual name='roller_n_rim_left_link_visual'>
          <pose>0 0 0 0 -0 0</pose>
          <geometry>
            <mesh>
              <scale>1 1 1</scale>
              <uri>/home/nikita/omni_ws/src/open_base/mesh/roller.stl</uri>
            </mesh>
          </geometry>
        </visual>
        <self_collide>0</self_collide>
        <enable_wind>0</enable_wind>
        <kinematic>0</kinematic>
      </link>
      <joint name='roller_ne_rim_left_joint' type='revolute'>
        <pose relative_to='rim_left_link'>0.009581 0.009581 -0.0055 -1.5708 -0 0.785398</pose>
        <parent>rim_left_link</parent>
        <child>roller_ne_rim_left_link</child>
        <axis>
          <xyz>0 0 1</xyz>
          <limit>
            <lower>-1e+16</lower>
            <upper>1e+16</upper>
          </limit>
          <dynamics>
            <spring_reference>0</spring_reference>
            <spring_stiffness>0</spring_stiffness>
          </dynamics>
        </axis>
      </joint>
      <link name='roller_ne_rim_left_link'>
        <pose relative_to='roller_ne_rim_left_joint'>0 0 0 0 -0 0</pose>
        <inertial>
          <pose>0 0 0 0 -0 0</pose>
          <mass>0.00113845</mass>
          <inertia>
            <ixx>2.53776e-08</ixx>
            <ixy>0</ixy>
            <ixz>0</ixz>
            <iyy>2.53776e-08</iyy>
            <iyz>0</iyz>
            <izz>1.47666e-08</izz>
          </inertia>
        </inertial>
        <collision name='roller_ne_rim_left_link_collision'>
          <pose>0 0 0 0 -0 0</pose>
          <geometry>
            <mesh>
              <scale>1 1 1</scale>
              <uri>/home/nikita/omni_ws/src/open_base/mesh/roller.stl</uri>
            </mesh>
          </geometry>
          <max_contacts>10</max_contacts>
          <surface>
            <contact>
              <ode/>
            </contact>
            <bounce/>
            <friction>
              <torsional>
                <ode/>
              </torsional>
              <ode/>
            </friction>
          </surface>
        </collision>
        <visual name='roller_ne_rim_left_link_visual'>
          <pose>0 0 0 0 -0 0</pose>
          <geometry>
            <mesh>
              <scale>1 1 1</scale>
              <uri>/home/nikita/omni_ws/src/open_base/mesh/roller.stl</uri>
            </mesh>
          </geometry>
        </visual>
        <self_collide>0</self_collide>
        <enable_wind>0</enable_wind>
        <kinematic>0</kinematic>
      </link>
      <joint name='roller_nw_rim_left_joint' type='revolute'>
        <pose relative_to='rim_left_link'>-0.009581 0.009581 -0.0055 -1.5708 -0 2.35619</pose>
        <parent>rim_left_link</parent>
        <child>roller_nw_rim_left_link</child>
        <axis>
          <xyz>0 0 1</xyz>
          <limit>
            <lower>-1e+16</lower>
            <upper>1e+16</upper>
          </limit>
          <dynamics>
            <spring_reference>0</spring_reference>
            <spring_stiffness>0</spring_stiffness>
          </dynamics>
        </axis>
      </joint>
      <link name='roller_nw_rim_left_link'>
        <pose relative_to='roller_nw_rim_left_joint'>0 0 0 0 -0 0</pose>
        <inertial>
          <pose>0 0 0 0 -0 0</pose>
          <mass>0.00113845</mass>
          <inertia>
            <ixx>2.53776e-08</ixx>
            <ixy>0</ixy>
            <ixz>0</ixz>
            <iyy>2.53776e-08</iyy>
            <iyz>0</iyz>
            <izz>1.47666e-08</izz>
          </inertia>
        </inertial>
        <collision name='roller_nw_rim_left_link_collision'>
          <pose>0 0 0 0 -0 0</pose>
          <geometry>
            <mesh>
              <scale>1 1 1</scale>
              <uri>/home/nikita/omni_ws/src/open_base/mesh/roller.stl</uri>
            </mesh>
          </geometry>
          <max_contacts>10</max_contacts>
          <surface>
            <contact>
              <ode/>
            </contact>
            <bounce/>
            <friction>
              <torsional>
                <ode/>
              </torsional>
              <ode/>
            </friction>
          </surface>
        </collision>
        <visual name='roller_nw_rim_left_link_visual'>
          <pose>0 0 0 0 -0 0</pose>
          <geometry>
            <mesh>
              <scale>1 1 1</scale>
              <uri>/home/nikita/omni_ws/src/open_base/mesh/roller.stl</uri>
            </mesh>
          </geometry>
        </visual>
        <self_collide>0</self_collide>
        <enable_wind>0</enable_wind>
        <kinematic>0</kinematic>
      </link>
      <joint name='roller_s_rim_left_joint' type='revolute'>
        <pose relative_to='rim_left_link'>0 -0.01355 0.0055 -1.5708 -0 -1.5708</pose>
        <parent>rim_left_link</parent>
        <child>roller_s_rim_left_link</child>
        <axis>
          <xyz>0 0 1</xyz>
          <limit>
            <lower>-1e+16</lower>
            <upper>1e+16</upper>
          </limit>
          <dynamics>
            <spring_reference>0</spring_reference>
            <spring_stiffness>0</spring_stiffness>
          </dynamics>
        </axis>
      </joint>
      <link name='roller_s_rim_left_link'>
        <pose relative_to='roller_s_rim_left_joint'>0 0 0 0 -0 0</pose>
        <inertial>
          <pose>0 0 0 0 -0 0</pose>
          <mass>0.00113845</mass>
          <inertia>
            <ixx>2.53776e-08</ixx>
            <ixy>0</ixy>
            <ixz>0</ixz>
            <iyy>2.53776e-08</iyy>
            <iyz>0</iyz>
            <izz>1.47666e-08</izz>
          </inertia>
        </inertial>
        <collision name='roller_s_rim_left_link_collision'>
          <pose>0 0 0 0 -0 0</pose>
          <geometry>
            <mesh>
              <scale>1 1 1</scale>
              <uri>/home/nikita/omni_ws/src/open_base/mesh/roller.stl</uri>
            </mesh>
          </geometry>
          <max_contacts>10</max_contacts>
          <surface>
            <contact>
              <ode/>
            </contact>
            <bounce/>
            <friction>
              <torsional>
                <ode/>
              </torsional>
              <ode/>
            </friction>
          </surface>
        </collision>
        <visual name='roller_s_rim_left_link_visual'>
          <pose>0 0 0 0 -0 0</pose>
          <geometry>
            <mesh>
              <scale>1 1 1</scale>
              <uri>/home/nikita/omni_ws/src/open_base/mesh/roller.stl</uri>
            </mesh>
          </geometry>
        </visual>
        <self_collide>0</self_collide>
        <enable_wind>0</enable_wind>
        <kinematic>0</kinematic>
      </link>
      <joint name='roller_se_rim_left_joint' type='revolute'>
        <pose relative_to='rim_left_link'>0.009581 -0.009581 -0.0055 -1.5708 0 -0.785398</pose>
        <parent>rim_left_link</parent>
        <child>roller_se_rim_left_link</child>
        <axis>
          <xyz>0 0 1</xyz>
          <limit>
            <lower>-1e+16</lower>
            <upper>1e+16</upper>
          </limit>
          <dynamics>
            <spring_reference>0</spring_reference>
            <spring_stiffness>0</spring_stiffness>
          </dynamics>
        </axis>
      </joint>
      <link name='roller_se_rim_left_link'>
        <pose relative_to='roller_se_rim_left_joint'>0 0 0 0 -0 0</pose>
        <inertial>
          <pose>0 0 0 0 -0 0</pose>
          <mass>0.00113845</mass>
          <inertia>
            <ixx>2.53776e-08</ixx>
            <ixy>0</ixy>
            <ixz>0</ixz>
            <iyy>2.53776e-08</iyy>
            <iyz>0</iyz>
            <izz>1.47666e-08</izz>
          </inertia>
        </inertial>
        <collision name='roller_se_rim_left_link_collision'>
          <pose>0 0 0 0 -0 0</pose>
          <geometry>
            <mesh>
              <scale>1 1 1</scale>
              <uri>/home/nikita/omni_ws/src/open_base/mesh/roller.stl</uri>
            </mesh>
          </geometry>
          <max_contacts>10</max_contacts>
          <surface>
            <contact>
              <ode/>
            </contact>
            <bounce/>
            <friction>
              <torsional>
                <ode/>
              </torsional>
              <ode/>
            </friction>
          </surface>
        </collision>
        <visual name='roller_se_rim_left_link_visual'>
          <pose>0 0 0 0 -0 0</pose>
          <geometry>
            <mesh>
              <scale>1 1 1</scale>
              <uri>/home/nikita/omni_ws/src/open_base/mesh/roller.stl</uri>
            </mesh>
          </geometry>
        </visual>
        <self_collide>0</self_collide>
        <enable_wind>0</enable_wind>
        <kinematic>0</kinematic>
      </link>
      <joint name='roller_sw_rim_left_joint' type='revolute'>
        <pose relative_to='rim_left_link'>-0.009581 -0.009581 -0.0055 -1.5708 -0 -2.35619</pose>
        <parent>rim_left_link</parent>
        <child>roller_sw_rim_left_link</child>
        <axis>
          <xyz>0 0 1</xyz>
          <limit>
            <lower>-1e+16</lower>
            <upper>1e+16</upper>
          </limit>
          <dynamics>
            <spring_reference>0</spring_reference>
            <spring_stiffness>0</spring_stiffness>
          </dynamics>
        </axis>
      </joint>
      <link name='roller_sw_rim_left_link'>
        <pose relative_to='roller_sw_rim_left_joint'>0 0 0 0 -0 0</pose>
        <inertial>
          <pose>0 0 0 0 -0 0</pose>
          <mass>0.00113845</mass>
          <inertia>
            <ixx>2.53776e-08</ixx>
            <ixy>0</ixy>
            <ixz>0</ixz>
            <iyy>2.53776e-08</iyy>
            <iyz>0</iyz>
            <izz>1.47666e-08</izz>
          </inertia>
        </inertial>
        <collision name='roller_sw_rim_left_link_collision'>
          <pose>0 0 0 0 -0 0</pose>
          <geometry>
            <mesh>
              <scale>1 1 1</scale>
              <uri>/home/nikita/omni_ws/src/open_base/mesh/roller.stl</uri>
            </mesh>
          </geometry>
          <max_contacts>10</max_contacts>
          <surface>
            <contact>
              <ode/>
            </contact>
            <bounce/>
            <friction>
              <torsional>
                <ode/>
              </torsional>
              <ode/>
            </friction>
          </surface>
        </collision>
        <visual name='roller_sw_rim_left_link_visual'>
          <pose>0 0 0 0 -0 0</pose>
          <geometry>
            <mesh>
              <scale>1 1 1</scale>
              <uri>/home/nikita/omni_ws/src/open_base/mesh/roller.stl</uri>
            </mesh>
          </geometry>
        </visual>
        <self_collide>0</self_collide>
        <enable_wind>0</enable_wind>
        <kinematic>0</kinematic>
      </link>
      <joint name='roller_w_rim_left_joint' type='revolute'>
        <pose relative_to='rim_left_link'>-0.01355 0 0.0055 -1.5708 -0 3.14159</pose>
        <parent>rim_left_link</parent>
        <child>roller_w_rim_left_link</child>
        <axis>
          <xyz>0 0 1</xyz>
          <limit>
            <lower>-1e+16</lower>
            <upper>1e+16</upper>
          </limit>
          <dynamics>
            <spring_reference>0</spring_reference>
            <spring_stiffness>0</spring_stiffness>
          </dynamics>
        </axis>
      </joint>
      <link name='roller_w_rim_left_link'>
        <pose relative_to='roller_w_rim_left_joint'>0 0 0 0 -0 0</pose>
        <inertial>
          <pose>0 0 0 0 -0 0</pose>
          <mass>0.00113845</mass>
          <inertia>
            <ixx>2.53776e-08</ixx>
            <ixy>0</ixy>
            <ixz>0</ixz>
            <iyy>2.53776e-08</iyy>
            <iyz>0</iyz>
            <izz>1.47666e-08</izz>
          </inertia>
        </inertial>
        <collision name='roller_w_rim_left_link_collision'>
          <pose>0 0 0 0 -0 0</pose>
          <geometry>
            <mesh>
              <scale>1 1 1</scale>
              <uri>/home/nikita/omni_ws/src/open_base/mesh/roller.stl</uri>
            </mesh>
          </geometry>
          <max_contacts>10</max_contacts>
          <surface>
            <contact>
              <ode/>
            </contact>
            <bounce/>
            <friction>
              <torsional>
                <ode/>
              </torsional>
              <ode/>
            </friction>
          </surface>
        </collision>
        <visual name='roller_w_rim_left_link_visual'>
          <pose>0 0 0 0 -0 0</pose>
          <geometry>
            <mesh>
              <scale>1 1 1</scale>
              <uri>/home/nikita/omni_ws/src/open_base/mesh/roller.stl</uri>
            </mesh>
          </geometry>
        </visual>
        <self_collide>0</self_collide>
        <enable_wind>0</enable_wind>
        <kinematic>0</kinematic>
      </link>
      <joint name='rim_right_joint' type='revolute'>
        <pose relative_to='origin_link'>0.034641 0.02 0.01905 1.5708 -0 -1.0472</pose>
        <parent>origin_link</parent>
        <child>rim_right_link</child>
        <axis>
          <xyz>0 0 1</xyz>
          <limit>
            <lower>-1e+16</lower>
            <upper>1e+16</upper>
          </limit>
          <dynamics>
            <spring_reference>0</spring_reference>
            <spring_stiffness>0</spring_stiffness>
          </dynamics>
        </axis>
      </joint>
      <link name='rim_right_link'>
        <pose relative_to='rim_right_joint'>0 0 0 0 -0 0</pose>
        <inertial>
          <pose>0 0 -0.000343 0 -0 0</pose>
          <mass>0.00835758</mass>
          <inertia>
            <ixx>6.63684e-07</ixx>
            <ixy>0</ixy>
            <ixz>0</ixz>
            <iyy>6.63684e-07</iyy>
            <iyz>0</iyz>
            <izz>9.40333e-07</izz>
          </inertia>
        </inertial>
        <collision name='rim_right_link_collision'>
          <pose>0 0 0 0 -0 0</pose>
          <geometry>
            <mesh>
              <scale>1 1 1</scale>
              <uri>/home/nikita/omni_ws/src/open_base/mesh/rim.stl</uri>
            </mesh>
          </geometry>
          <max_contacts>10</max_contacts>
          <surface>
            <contact>
              <ode/>
            </contact>
            <bounce/>
            <friction>
              <torsional>
                <ode/>
              </torsional>
              <ode/>
            </friction>
          </surface>
        </collision>
        <visual name='rim_right_link_visual'>
          <pose>0 0 0 0 -0 0</pose>
          <geometry>
            <mesh>
              <scale>1 1 1</scale>
              <uri>/home/nikita/omni_ws/src/open_base/mesh/rim.stl</uri>
            </mesh>
          </geometry>
        </visual>
        <self_collide>0</self_collide>
        <enable_wind>0</enable_wind>
        <kinematic>0</kinematic>
      </link>
      <joint name='roller_e_rim_right_joint' type='revolute'>
        <pose relative_to='rim_right_link'>0.01355 0 0.0055 -1.5708 0 0</pose>
        <parent>rim_right_link</parent>
        <child>roller_e_rim_right_link</child>
        <axis>
          <xyz>0 0 1</xyz>
          <limit>
            <lower>-1e+16</lower>
            <upper>1e+16</upper>
          </limit>
          <dynamics>
            <spring_reference>0</spring_reference>
            <spring_stiffness>0</spring_stiffness>
          </dynamics>
        </axis>
      </joint>
      <link name='roller_e_rim_right_link'>
        <pose relative_to='roller_e_rim_right_joint'>0 0 0 0 -0 0</pose>
        <inertial>
          <pose>0 0 0 0 -0 0</pose>
          <mass>0.00113845</mass>
          <inertia>
            <ixx>2.53776e-08</ixx>
            <ixy>0</ixy>
            <ixz>0</ixz>
            <iyy>2.53776e-08</iyy>
            <iyz>0</iyz>
            <izz>1.47666e-08</izz>
          </inertia>
        </inertial>
        <collision name='roller_e_rim_right_link_collision'>
          <pose>0 0 0 0 -0 0</pose>
          <geometry>
            <mesh>
              <scale>1 1 1</scale>
              <uri>/home/nikita/omni_ws/src/open_base/mesh/roller.stl</uri>
            </mesh>
          </geometry>
          <max_contacts>10</max_contacts>
          <surface>
            <contact>
              <ode/>
            </contact>
            <bounce/>
            <friction>
              <torsional>
                <ode/>
              </torsional>
              <ode/>
            </friction>
          </surface>
        </collision>
        <visual name='roller_e_rim_right_link_visual'>
          <pose>0 0 0 0 -0 0</pose>
          <geometry>
            <mesh>
              <scale>1 1 1</scale>
              <uri>/home/nikita/omni_ws/src/open_base/mesh/roller.stl</uri>
            </mesh>
          </geometry>
        </visual>
        <self_collide>0</self_collide>
        <enable_wind>0</enable_wind>
        <kinematic>0</kinematic>
      </link>
      <joint name='roller_n_rim_right_joint' type='revolute'>
        <pose relative_to='rim_right_link'>0 0.01355 0.0055 -1.5708 0 1.5708</pose>
        <parent>rim_right_link</parent>
        <child>roller_n_rim_right_link</child>
        <axis>
          <xyz>0 0 1</xyz>
          <limit>
            <lower>-1e+16</lower>
            <upper>1e+16</upper>
          </limit>
          <dynamics>
            <spring_reference>0</spring_reference>
            <spring_stiffness>0</spring_stiffness>
          </dynamics>
        </axis>
      </joint>
      <link name='roller_n_rim_right_link'>
        <pose relative_to='roller_n_rim_right_joint'>0 0 0 0 -0 0</pose>
        <inertial>
          <pose>0 0 0 0 -0 0</pose>
          <mass>0.00113845</mass>
          <inertia>
            <ixx>2.53776e-08</ixx>
            <ixy>0</ixy>
            <ixz>0</ixz>
            <iyy>2.53776e-08</iyy>
            <iyz>0</iyz>
            <izz>1.47666e-08</izz>
          </inertia>
        </inertial>
        <collision name='roller_n_rim_right_link_collision'>
          <pose>0 0 0 0 -0 0</pose>
          <geometry>
            <mesh>
              <scale>1 1 1</scale>
              <uri>/home/nikita/omni_ws/src/open_base/mesh/roller.stl</uri>
            </mesh>
          </geometry>
          <max_contacts>10</max_contacts>
          <surface>
            <contact>
              <ode/>
            </contact>
            <bounce/>
            <friction>
              <torsional>
                <ode/>
              </torsional>
              <ode/>
            </friction>
          </surface>
        </collision>
        <visual name='roller_n_rim_right_link_visual'>
          <pose>0 0 0 0 -0 0</pose>
          <geometry>
            <mesh>
              <scale>1 1 1</scale>
              <uri>/home/nikita/omni_ws/src/open_base/mesh/roller.stl</uri>
            </mesh>
          </geometry>
        </visual>
        <self_collide>0</self_collide>
        <enable_wind>0</enable_wind>
        <kinematic>0</kinematic>
      </link>
      <joint name='roller_ne_rim_right_joint' type='revolute'>
        <pose relative_to='rim_right_link'>0.009581 0.009581 -0.0055 -1.5708 -0 0.785398</pose>
        <parent>rim_right_link</parent>
        <child>roller_ne_rim_right_link</child>
        <axis>
          <xyz>0 0 1</xyz>
          <limit>
            <lower>-1e+16</lower>
            <upper>1e+16</upper>
          </limit>
          <dynamics>
            <spring_reference>0</spring_reference>
            <spring_stiffness>0</spring_stiffness>
          </dynamics>
        </axis>
      </joint>
      <link name='roller_ne_rim_right_link'>
        <pose relative_to='roller_ne_rim_right_joint'>0 0 0 0 -0 0</pose>
        <inertial>
          <pose>0 0 0 0 -0 0</pose>
          <mass>0.00113845</mass>
          <inertia>
            <ixx>2.53776e-08</ixx>
            <ixy>0</ixy>
            <ixz>0</ixz>
            <iyy>2.53776e-08</iyy>
            <iyz>0</iyz>
            <izz>1.47666e-08</izz>
          </inertia>
        </inertial>
        <collision name='roller_ne_rim_right_link_collision'>
          <pose>0 0 0 0 -0 0</pose>
          <geometry>
            <mesh>
              <scale>1 1 1</scale>
              <uri>/home/nikita/omni_ws/src/open_base/mesh/roller.stl</uri>
            </mesh>
          </geometry>
          <max_contacts>10</max_contacts>
          <surface>
            <contact>
              <ode/>
            </contact>
            <bounce/>
            <friction>
              <torsional>
                <ode/>
              </torsional>
              <ode/>
            </friction>
          </surface>
        </collision>
        <visual name='roller_ne_rim_right_link_visual'>
          <pose>0 0 0 0 -0 0</pose>
          <geometry>
            <mesh>
              <scale>1 1 1</scale>
              <uri>/home/nikita/omni_ws/src/open_base/mesh/roller.stl</uri>
            </mesh>
          </geometry>
        </visual>
        <self_collide>0</self_collide>
        <enable_wind>0</enable_wind>
        <kinematic>0</kinematic>
      </link>
      <joint name='roller_nw_rim_right_joint' type='revolute'>
        <pose relative_to='rim_right_link'>-0.009581 0.009581 -0.0055 -1.5708 -0 2.35619</pose>
        <parent>rim_right_link</parent>
        <child>roller_nw_rim_right_link</child>
        <axis>
          <xyz>0 0 1</xyz>
          <limit>
            <lower>-1e+16</lower>
            <upper>1e+16</upper>
          </limit>
          <dynamics>
            <spring_reference>0</spring_reference>
            <spring_stiffness>0</spring_stiffness>
          </dynamics>
        </axis>
      </joint>
      <link name='roller_nw_rim_right_link'>
        <pose relative_to='roller_nw_rim_right_joint'>0 0 0 0 -0 0</pose>
        <inertial>
          <pose>0 0 0 0 -0 0</pose>
          <mass>0.00113845</mass>
          <inertia>
            <ixx>2.53776e-08</ixx>
            <ixy>0</ixy>
            <ixz>0</ixz>
            <iyy>2.53776e-08</iyy>
            <iyz>0</iyz>
            <izz>1.47666e-08</izz>
          </inertia>
        </inertial>
        <collision name='roller_nw_rim_right_link_collision'>
          <pose>0 0 0 0 -0 0</pose>
          <geometry>
            <mesh>
              <scale>1 1 1</scale>
              <uri>/home/nikita/omni_ws/src/open_base/mesh/roller.stl</uri>
            </mesh>
          </geometry>
          <max_contacts>10</max_contacts>
          <surface>
            <contact>
              <ode/>
            </contact>
            <bounce/>
            <friction>
              <torsional>
                <ode/>
              </torsional>
              <ode/>
            </friction>
          </surface>
        </collision>
        <visual name='roller_nw_rim_right_link_visual'>
          <pose>0 0 0 0 -0 0</pose>
          <geometry>
            <mesh>
              <scale>1 1 1</scale>
              <uri>/home/nikita/omni_ws/src/open_base/mesh/roller.stl</uri>
            </mesh>
          </geometry>
        </visual>
        <self_collide>0</self_collide>
        <enable_wind>0</enable_wind>
        <kinematic>0</kinematic>
      </link>
      <joint name='roller_s_rim_right_joint' type='revolute'>
        <pose relative_to='rim_right_link'>0 -0.01355 0.0055 -1.5708 -0 -1.5708</pose>
        <parent>rim_right_link</parent>
        <child>roller_s_rim_right_link</child>
        <axis>
          <xyz>0 0 1</xyz>
          <limit>
            <lower>-1e+16</lower>
            <upper>1e+16</upper>
          </limit>
          <dynamics>
            <spring_reference>0</spring_reference>
            <spring_stiffness>0</spring_stiffness>
          </dynamics>
        </axis>
      </joint>
      <link name='roller_s_rim_right_link'>
        <pose relative_to='roller_s_rim_right_joint'>0 0 0 0 -0 0</pose>
        <inertial>
          <pose>0 0 0 0 -0 0</pose>
          <mass>0.00113845</mass>
          <inertia>
            <ixx>2.53776e-08</ixx>
            <ixy>0</ixy>
            <ixz>0</ixz>
            <iyy>2.53776e-08</iyy>
            <iyz>0</iyz>
            <izz>1.47666e-08</izz>
          </inertia>
        </inertial>
        <collision name='roller_s_rim_right_link_collision'>
          <pose>0 0 0 0 -0 0</pose>
          <geometry>
            <mesh>
              <scale>1 1 1</scale>
              <uri>/home/nikita/omni_ws/src/open_base/mesh/roller.stl</uri>
            </mesh>
          </geometry>
          <max_contacts>10</max_contacts>
          <surface>
            <contact>
              <ode/>
            </contact>
            <bounce/>
            <friction>
              <torsional>
                <ode/>
              </torsional>
              <ode/>
            </friction>
          </surface>
        </collision>
        <visual name='roller_s_rim_right_link_visual'>
          <pose>0 0 0 0 -0 0</pose>
          <geometry>
            <mesh>
              <scale>1 1 1</scale>
              <uri>/home/nikita/omni_ws/src/open_base/mesh/roller.stl</uri>
            </mesh>
          </geometry>
        </visual>
        <self_collide>0</self_collide>
        <enable_wind>0</enable_wind>
        <kinematic>0</kinematic>
      </link>
      <joint name='roller_se_rim_right_joint' type='revolute'>
        <pose relative_to='rim_right_link'>0.009581 -0.009581 -0.0055 -1.5708 0 -0.785398</pose>
        <parent>rim_right_link</parent>
        <child>roller_se_rim_right_link</child>
        <axis>
          <xyz>0 0 1</xyz>
          <limit>
            <lower>-1e+16</lower>
            <upper>1e+16</upper>
          </limit>
          <dynamics>
            <spring_reference>0</spring_reference>
            <spring_stiffness>0</spring_stiffness>
          </dynamics>
        </axis>
      </joint>
      <link name='roller_se_rim_right_link'>
        <pose relative_to='roller_se_rim_right_joint'>0 0 0 0 -0 0</pose>
        <inertial>
          <pose>0 0 0 0 -0 0</pose>
          <mass>0.00113845</mass>
          <inertia>
            <ixx>2.53776e-08</ixx>
            <ixy>0</ixy>
            <ixz>0</ixz>
            <iyy>2.53776e-08</iyy>
            <iyz>0</iyz>
            <izz>1.47666e-08</izz>
          </inertia>
        </inertial>
        <collision name='roller_se_rim_right_link_collision'>
          <pose>0 0 0 0 -0 0</pose>
          <geometry>
            <mesh>
              <scale>1 1 1</scale>
              <uri>/home/nikita/omni_ws/src/open_base/mesh/roller.stl</uri>
            </mesh>
          </geometry>
          <max_contacts>10</max_contacts>
          <surface>
            <contact>
              <ode/>
            </contact>
            <bounce/>
            <friction>
              <torsional>
                <ode/>
              </torsional>
              <ode/>
            </friction>
          </surface>
        </collision>
        <visual name='roller_se_rim_right_link_visual'>
          <pose>0 0 0 0 -0 0</pose>
          <geometry>
            <mesh>
              <scale>1 1 1</scale>
              <uri>/home/nikita/omni_ws/src/open_base/mesh/roller.stl</uri>
            </mesh>
          </geometry>
        </visual>
        <self_collide>0</self_collide>
        <enable_wind>0</enable_wind>
        <kinematic>0</kinematic>
      </link>
      <joint name='roller_sw_rim_right_joint' type='revolute'>
        <pose relative_to='rim_right_link'>-0.009581 -0.009581 -0.0055 -1.5708 -0 -2.35619</pose>
        <parent>rim_right_link</parent>
        <child>roller_sw_rim_right_link</child>
        <axis>
          <xyz>0 0 1</xyz>
          <limit>
            <lower>-1e+16</lower>
            <upper>1e+16</upper>
          </limit>
          <dynamics>
            <spring_reference>0</spring_reference>
            <spring_stiffness>0</spring_stiffness>
          </dynamics>
        </axis>
      </joint>
      <link name='roller_sw_rim_right_link'>
        <pose relative_to='roller_sw_rim_right_joint'>0 0 0 0 -0 0</pose>
        <inertial>
          <pose>0 0 0 0 -0 0</pose>
          <mass>0.00113845</mass>
          <inertia>
            <ixx>2.53776e-08</ixx>
            <ixy>0</ixy>
            <ixz>0</ixz>
            <iyy>2.53776e-08</iyy>
            <iyz>0</iyz>
            <izz>1.47666e-08</izz>
          </inertia>
        </inertial>
        <collision name='roller_sw_rim_right_link_collision'>
          <pose>0 0 0 0 -0 0</pose>
          <geometry>
            <mesh>
              <scale>1 1 1</scale>
              <uri>/home/nikita/omni_ws/src/open_base/mesh/roller.stl</uri>
            </mesh>
          </geometry>
          <max_contacts>10</max_contacts>
          <surface>
            <contact>
              <ode/>
            </contact>
            <bounce/>
            <friction>
              <torsional>
                <ode/>
              </torsional>
              <ode/>
            </friction>
          </surface>
        </collision>
        <visual name='roller_sw_rim_right_link_visual'>
          <pose>0 0 0 0 -0 0</pose>
          <geometry>
            <mesh>
              <scale>1 1 1</scale>
              <uri>/home/nikita/omni_ws/src/open_base/mesh/roller.stl</uri>
            </mesh>
          </geometry>
        </visual>
        <self_collide>0</self_collide>
        <enable_wind>0</enable_wind>
        <kinematic>0</kinematic>
      </link>
      <joint name='roller_w_rim_right_joint' type='revolute'>
        <pose relative_to='rim_right_link'>-0.01355 0 0.0055 -1.5708 -0 3.14159</pose>
        <parent>rim_right_link</parent>
        <child>roller_w_rim_right_link</child>
        <axis>
          <xyz>0 0 1</xyz>
          <limit>
            <lower>-1e+16</lower>
            <upper>1e+16</upper>
          </limit>
          <dynamics>
            <spring_reference>0</spring_reference>
            <spring_stiffness>0</spring_stiffness>
          </dynamics>
        </axis>
      </joint>
      <link name='roller_w_rim_right_link'>
        <pose relative_to='roller_w_rim_right_joint'>0 0 0 0 -0 0</pose>
        <inertial>
          <pose>0 0 0 0 -0 0</pose>
          <mass>0.00113845</mass>
          <inertia>
            <ixx>2.53776e-08</ixx>
            <ixy>0</ixy>
            <ixz>0</ixz>
            <iyy>2.53776e-08</iyy>
            <iyz>0</iyz>
            <izz>1.47666e-08</izz>
          </inertia>
        </inertial>
        <collision name='roller_w_rim_right_link_collision'>
          <pose>0 0 0 0 -0 0</pose>
          <geometry>
            <mesh>
              <scale>1 1 1</scale>
              <uri>/home/nikita/omni_ws/src/open_base/mesh/roller.stl</uri>
            </mesh>
          </geometry>
          <max_contacts>10</max_contacts>
          <surface>
            <contact>
              <ode/>
            </contact>
            <bounce/>
            <friction>
              <torsional>
                <ode/>
              </torsional>
              <ode/>
            </friction>
          </surface>
        </collision>
        <visual name='roller_w_rim_right_link_visual'>
          <pose>0 0 0 0 -0 0</pose>
          <geometry>
            <mesh>
              <scale>1 1 1</scale>
              <uri>/home/nikita/omni_ws/src/open_base/mesh/roller.stl</uri>
            </mesh>
          </geometry>
        </visual>
        <self_collide>0</self_collide>
        <enable_wind>0</enable_wind>
        <kinematic>0</kinematic>
      </link>
      <static>0</static>
      <plugin name='gazebo_ros_control' filename='libgazebo_ros_control.so'>
        <robotNamespace>/open_base</robotNamespace>
      </plugin>
      <pose>0 0 0 0 -0 0</pose>
    </model>
    <model name='unit_box'>
      <pose>0.013036 1.23233 0.5 0 -0 0</pose>
      <link name='link'>
        <inertial>
          <mass>1</mass>
          <inertia>
            <ixx>0.166667</ixx>
            <ixy>0</ixy>
            <ixz>0</ixz>
            <iyy>0.166667</iyy>
            <iyz>0</iyz>
            <izz>0.166667</izz>
          </inertia>
          <pose>0 0 0 0 -0 0</pose>
        </inertial>
        <collision name='collision'>
          <geometry>
            <box>
              <size>1 1 1</size>
            </box>
          </geometry>
          <max_contacts>10</max_contacts>
          <surface>
            <contact>
              <ode/>
            </contact>
            <bounce/>
            <friction>
              <torsional>
                <ode/>
              </torsional>
              <ode/>
            </friction>
          </surface>
        </collision>
        <visual name='visual'>
          <geometry>
            <box>
              <size>1 1 1</size>
            </box>
          </geometry>
          <material>
            <script>
              <name>Gazebo/Grey</name>
              <uri>file://media/materials/scripts/gazebo.material</uri>
            </script>
          </material>
        </visual>
        <self_collide>0</self_collide>
        <enable_wind>0</enable_wind>
        <kinematic>0</kinematic>
      </link>
    </model>
    <state world_name='default'>
      <sim_time>0 0</sim_time>
      <real_time>0 0</real_time>
      <wall_time>1648552172 363280583</wall_time>
      <iterations>0</iterations>
      <model name='ground_plane'>
        <pose>0 0 0 0 -0 0</pose>
        <scale>1 1 1</scale>
        <link name='link'>
          <pose>0 0 0 0 -0 0</pose>
          <velocity>0 0 0 0 -0 0</velocity>
          <acceleration>0 0 0 0 -0 0</acceleration>
          <wrench>0 0 0 0 -0 0</wrench>
        </link>
      </model>
      <model name='open_base'>
        <pose>0 0 0 0 -0 0</pose>
        <scale>1 1 1</scale>
        <link name='origin_link'>
          <pose>0 0 0 0 -0 0</pose>
          <velocity>0 0 0 0 -0 0</velocity>
          <acceleration>0 0 0 0 -0 0</acceleration>
          <wrench>0 0 0 0 -0 0</wrench>
        </link>
        <link name='rim_back_link'>
          <pose>0 -0.04 0.01905 1.5708 -0 3.14159</pose>
          <velocity>0 0 0 0 -0 0</velocity>
          <acceleration>0 0 0 0 -0 0</acceleration>
          <wrench>0 0 0 0 -0 0</wrench>
        </link>
        <link name='rim_left_link'>
          <pose>-0.034641 0.02 0.01905 1.5708 -0 1.0472</pose>
          <velocity>0 0 0 0 -0 0</velocity>
          <acceleration>0 0 0 0 -0 0</acceleration>
          <wrench>0 0 0 0 -0 0</wrench>
        </link>
        <link name='rim_right_link'>
          <pose>0.034641 0.02 0.01905 1.5708 -0 -1.0472</pose>
          <velocity>0 0 0 0 -0 0</velocity>
          <acceleration>0 0 0 0 -0 0</acceleration>
          <wrench>0 0 0 0 -0 0</wrench>
        </link>
        <link name='roller_e_rim_back_link'>
          <pose>-0.01355 -0.0345 0.01905 0 -0 3.14159</pose>
          <velocity>0 0 0 0 -0 0</velocity>
          <acceleration>0 0 0 0 -0 0</acceleration>
          <wrench>0 0 0 0 -0 0</wrench>
        </link>
        <link name='roller_e_rim_left_link'>
          <pose>-0.023103 0.028985 0.01905 0 -0 1.0472</pose>
          <velocity>0 0 0 0 -0 0</velocity>
          <acceleration>0 0 0 0 -0 0</acceleration>
          <wrench>0 0 0 0 -0 0</wrench>
        </link>
        <link name='roller_e_rim_right_link'>
          <pose>0.036653 0.005515 0.01905 0 0 -1.0472</pose>
          <velocity>0 0 0 0 -0 0</velocity>
          <acceleration>0 0 0 0 -0 0</acceleration>
          <wrench>0 0 0 0 -0 0</wrench>
        </link>
        <link name='roller_n_rim_back_link'>
          <pose>0 -0.0345 0.0326 2.35619 -1.57079 0.785396</pose>
          <velocity>0 0 0 0 -0 0</velocity>
          <acceleration>0 0 0 0 -0 0</acceleration>
          <wrench>0 0 0 0 -0 0</wrench>
        </link>
        <link name='roller_n_rim_left_link'>
          <pose>-0.029878 0.01725 0.0326 2.35619 -1.57079 -1.30899</pose>
          <velocity>0 0 0 0 -0 0</velocity>
          <acceleration>0 0 0 0 -0 0</acceleration>
          <wrench>0 0 0 0 -0 0</wrench>
        </link>
        <link name='roller_n_rim_right_link'>
          <pose>0.029878 0.01725 0.0326 2.35619 -1.57079 2.87979</pose>
          <velocity>0 0 0 0 -0 0</velocity>
          <acceleration>0 0 0 0 -0 0</acceleration>
          <wrench>0 0 0 0 -0 0</wrench>
        </link>
        <link name='roller_ne_rim_back_link'>
          <pose>-0.009581 -0.0455 0.028631 2e-06 -0.785398 3.14159</pose>
          <velocity>0 0 0 0 -0 0</velocity>
          <acceleration>0 0 0 0 -0 0</acceleration>
          <wrench>0 0 0 0 -0 0</wrench>
        </link>
        <link name='roller_ne_rim_left_link'>
          <pose>-0.034614 0.031047 0.028631 2e-06 -0.785398 1.0472</pose>
          <velocity>0 0 0 0 -0 0</velocity>
          <acceleration>0 0 0 0 -0 0</acceleration>
          <wrench>0 0 0 0 -0 0</wrench>
        </link>
        <link name='roller_ne_rim_right_link'>
          <pose>0.044195 0.014453 0.028631 2e-06 -0.785398 -1.0472</pose>
          <velocity>0 0 0 0 -0 0</velocity>
          <acceleration>0 0 0 0 -0 0</acceleration>
          <wrench>0 0 0 0 -0 0</wrench>
        </link>
        <link name='roller_nw_rim_back_link'>
          <pose>0.009581 -0.0455 0.028631 3.14158 -0.785403 1e-06</pose>
          <velocity>0 0 0 0 -0 0</velocity>
          <acceleration>0 0 0 0 -0 0</acceleration>
          <wrench>0 0 0 0 -0 0</wrench>
        </link>
        <link name='roller_nw_rim_left_link'>
          <pose>-0.044195 0.014453 0.028631 3.14158 -0.785403 -2.09439</pose>
          <velocity>0 0 0 0 -0 0</velocity>
          <acceleration>0 0 0 0 -0 0</acceleration>
          <wrench>0 0 0 0 -0 0</wrench>
        </link>
        <link name='roller_nw_rim_right_link'>
          <pose>0.034614 0.031047 0.028631 3.14158 -0.785403 2.0944</pose>
          <velocity>0 0 0 0 -0 0</velocity>
          <acceleration>0 0 0 0 -0 0</acceleration>
          <wrench>0 0 0 0 -0 0</wrench>
        </link>
        <link name='roller_s_rim_back_link'>
          <pose>0 -0.0345 0.0055 2.35619 1.57079 -0.785401</pose>
          <velocity>0 0 0 0 -0 0</velocity>
          <acceleration>0 0 0 0 -0 0</acceleration>
          <wrench>0 0 0 0 -0 0</wrench>
        </link>
        <link name='roller_s_rim_left_link'>
          <pose>-0.029878 0.01725 0.0055 2.35619 1.57079 -2.87979</pose>
          <velocity>0 0 0 0 -0 0</velocity>
          <acceleration>0 0 0 0 -0 0</acceleration>
          <wrench>0 0 0 0 -0 0</wrench>
        </link>
        <link name='roller_s_rim_right_link'>
          <pose>0.029878 0.01725 0.0055 2.35619 1.57079 1.30899</pose>
          <velocity>0 0 0 0 -0 0</velocity>
          <acceleration>0 0 0 0 -0 0</acceleration>
          <wrench>0 0 0 0 -0 0</wrench>
        </link>
        <link name='roller_se_rim_back_link'>
          <pose>-0.009581 -0.0455 0.009469 2e-06 0.785398 -3.14159</pose>
          <velocity>0 0 0 0 -0 0</velocity>
          <acceleration>0 0 0 0 -0 0</acceleration>
          <wrench>0 0 0 0 -0 0</wrench>
        </link>
        <link name='roller_se_rim_left_link'>
          <pose>-0.034614 0.031047 0.009469 2e-06 0.785398 1.0472</pose>
          <velocity>0 0 0 0 -0 0</velocity>
          <acceleration>0 0 0 0 -0 0</acceleration>
          <wrench>0 0 0 0 -0 0</wrench>
        </link>
        <link name='roller_se_rim_right_link'>
          <pose>0.044195 0.014453 0.009469 2e-06 0.785398 -1.0472</pose>
          <velocity>0 0 0 0 -0 0</velocity>
          <acceleration>0 0 0 0 -0 0</acceleration>
          <wrench>0 0 0 0 -0 0</wrench>
        </link>
        <link name='roller_sw_rim_back_link'>
          <pose>0.009581 -0.0455 0.009469 3.14158 0.785403 -6e-06</pose>
          <velocity>0 0 0 0 -0 0</velocity>
          <acceleration>0 0 0 0 -0 0</acceleration>
          <wrench>0 0 0 0 -0 0</wrench>
        </link>
        <link name='roller_sw_rim_left_link'>
          <pose>-0.044195 0.014453 0.009469 3.14158 0.785403 -2.0944</pose>
          <velocity>0 0 0 0 -0 0</velocity>
          <acceleration>0 0 0 0 -0 0</acceleration>
          <wrench>0 0 0 0 -0 0</wrench>
        </link>
        <link name='roller_sw_rim_right_link'>
          <pose>0.034614 0.031047 0.009469 3.14158 0.785403 2.09439</pose>
          <velocity>0 0 0 0 -0 0</velocity>
          <acceleration>0 0 0 0 -0 0</acceleration>
          <wrench>0 0 0 0 -0 0</wrench>
        </link>
        <link name='roller_w_rim_back_link'>
          <pose>0.01355 -0.0345 0.01905 3.14159 -3e-06 -3e-06</pose>
          <velocity>0 0 0 0 -0 0</velocity>
          <acceleration>0 0 0 0 -0 0</acceleration>
          <wrench>0 0 0 0 -0 0</wrench>
        </link>
        <link name='roller_w_rim_left_link'>
          <pose>-0.036653 0.005515 0.01905 3.14159 -3e-06 -2.09439</pose>
          <velocity>0 0 0 0 -0 0</velocity>
          <acceleration>0 0 0 0 -0 0</acceleration>
          <wrench>0 0 0 0 -0 0</wrench>
        </link>
        <link name='roller_w_rim_right_link'>
          <pose>0.023103 0.028985 0.01905 3.14159 -3e-06 2.09439</pose>
          <velocity>0 0 0 0 -0 0</velocity>
          <acceleration>0 0 0 0 -0 0</acceleration>
          <wrench>0 0 0 0 -0 0</wrench>
        </link>
      </model>
      <model name='unit_box'>
        <pose>0.013036 1.23233 0.5 0 -0 0</pose>
        <scale>1 1 1</scale>
        <link name='link'>
          <pose>0.013036 1.23233 0.5 0 -0 0</pose>
          <velocity>0 0 0 0 -0 0</velocity>
          <acceleration>0 0 0 0 -0 0</acceleration>
          <wrench>0 0 0 0 -0 0</wrench>
        </link>
      </model>
      <light name='sun'>
        <pose>0 0 10 0 -0 0</pose>
      </light>
    </state>
    <gui fullscreen='0'>
      <camera name='user_camera'>
        <pose>5 -5 2 0 0.275643 2.35619</pose>
        <view_controller>orbit</view_controller>
        <projection_type>perspective</projection_type>
      </camera>
    </gui>
  </world>
</sdf>
